Workbook

Sheet 日常水質
A1: 筒賀水質管理センター 維持管理週報 | M1: 令和8年3月
I3: 46083 | J3: =I3+1 | K3: =J3+1 | L3: =K3+1 | M3: =L3+1 | N3: =M3+3 | O3: 平均
A4: 全日電力量 | G4: Kｗｈ
A5: 力測電力量 | G5: Kｗｈ
A6: 無効電力量 | G6: Kvar
A7: デマンド | G7: Kw
A8: 水道使用量 | G8: ㎥
A9: 軽油（残量） | G9: ℓ
A10: 返送汚泥流量（№1） | G10: ㎥
A11: 返送汚泥流量（№2） | G11: ㎥
A12: 放流流量 | G12: ㎥
A13: 日 常 水 質 測 定 結 果
A14: 測 定 項 目 | I14: 測定場所 | J14: =I3 | K14: =J3 | L14: =K3 | M14: =L3 | N14: =M3 | O14: =O3
I15: 測定者 | J15: 山根 悠貴 | K15: 山根 悠貴 | L15: 山根 悠貴 | M15: 山根 悠貴 | N15: 山根 悠貴
A16: 水温 | G16: ℃ | I16: 流入
I17: ディッチ、１
I18: ディッチ、２
I19: 放流
A20: 外観 | C20: 油膜・色合 | G20: 有無 | I20: 流入
I21: ディッチ、１
I22: ディッチ、２
I23: 放流
A24: 透視度 | G24: ｃｍ | I24: 流入水
I25: 放流水
A26: 臭気 | C26: 腐敗臭 | G26: 有無 | I26: 流入
I27: ディッチ、１
I28: ディッチ、２
I29: 放流
A30: PH | G30: ― | I30: 流入
I31: ディッチ、１
I32: ディッチ、２
I33: 放流
A34: SV | C34: SV・30 | G34: ％ | I34: １系
C35: SV・２４ｈ
A36: SV | C36: SV・30 | G36: ％ | I36: ２系
C37: SV・２４ｈ
A38: 反応槽 | C38: MLSS | G38: ㎎/ℓ | I38: 1系
I39: 2系
A40: 汚泥界面 | G40: ｃｍ | I40: １系終沈
I41: ２系終沈
...

Sheet 運転管理月報
A1: 筒賀水質管理センター運転管理月報 | J1: 令和8年 3月分
A2: 日付 | B2: 曜日 | C2: 全日電力量読み値 | D2: 力測電力量読み値 | E2: 無効電力量読み値 | F2: 上水使用量読み値 | G2: 固形塩素 | H2: 脱水ケーキ | J2: No.1 | L2: No.2 | N2: 放流流量
G3: 使用量 | H3: 発生量 | I3: 搬出量 | J3: 返送汚泥 | L3: 返送汚泥
J4: 流 量 | L4: 流 量
C5: kwh | D5: kwh | E5: kvarh | F5: ㎥ | G5: kg | H5: ｔ | I5: ｔ | J5: ㎥ | L5: ㎥ | N5: ㎥
A6: 46082 | B6: =TEXT(A6,"aaa")
A7: =A6+1 | B7: =TEXT(A7,"aaa") | K7: =IF(OR(J7="",J6=""),"",J7-J6) | M7: =IF(OR(L7="",L6=""),"",L7-L6)
A8: =A7+1 | B8: =TEXT(A8,"aaa") | K8: =IF(OR(J8="",J7=""),"",J8-J7) | M8: =IF(OR(L8="",L7=""),"",L8-L7)
A9: =A8+1 | B9: =TEXT(A9,"aaa") | K9: =IF(OR(J9="",J8=""),"",J9-J8) | M9: =IF(OR(L9="",L8=""),"",L9-L8)
A10: =A9+1 | B10: =TEXT(A10,"aaa") | K10: =IF(OR(J10="",J9=""),"",J10-J9) | M10: =IF(OR(L10="",L9=""),"",L10-L9)
A11: =A10+1 | B11: =TEXT(A11,"aaa") | K11: =IF(OR(J11="",J10=""),"",J11-J10) | M11: =IF(OR(L11="",L10=""),"",L11-L10)
A12: =A11+1 | B12: =TEXT(A12,"aaa") | K12: =IF(OR(J12="",J11=""),"",J12-J11) | M12: =IF(OR(L12="",L11=""),"",L12-L11)
A13: =A12+1 | B13: =TEXT(A13,"aaa") | K13: =IF(OR(J13="",J12=""),"",J13-J12) | M13: =IF(OR(L13="",L12=""),"",L13-L12)
A14: =A13+1 | B14: =TEXT(A14,"aaa") | K14: =IF(OR(J14="",J13=""),"",J14-J13) | M14: =IF(OR(L14="",L13=""),"",L14-L13)
A15: =A14+1 | B15: =TEXT(A15,"aaa") | K15: =IF(OR(J15="",J14=""),"",J15-J14) | M15: =IF(OR(L15="",L14=""),"",L15-L14)
A16: =A15+1 | B16: =TEXT(A16,"aaa") | K16: =IF(OR(J16="",J15=""),"",J16-J15) | M16: =IF(OR(L16="",L15=""),"",L16-L15)
A17: =A16+1 | B17: =TEXT(A17,"aaa") | K17: =IF(OR(J17="",J16=""),"",J17-J16) | M17: =IF(OR(L17="",L16=""),"",L17-L16)
A18: =A17+1 | B18: =TEXT(A18,"aaa") | K18: =IF(OR(J18="",J17=""),"",J18-J17) | M18: =IF(OR(L18="",L17=""),"",L18-L17)
... A36: =A35+1 | B36: =TEXT(A36,"aaa") | K36: =IF(OR(J36="",J35=""),"",J36-J35) | M36: =IF(OR(L36="",L35=""),"",L36-L35)
A37: 46110 | B37: 日 | K37: =IF(OR(J37="",J36=""),"",J37-J36) | M37: =IF(OR(L37="",L36=""),"",L37-L36)
A38: 46111 | B38: 月 | K38: =IF(OR(J38="",J37=""),"",J38-J37) | M38: =IF(OR(L38="",L37=""),"",L38-L37)
A39: 46112 | B39: 火 | K39: =IF(OR(J39="",J38=""),"",J39-J38) | M39: =IF(OR(L39="",L38=""),"",L39-L38)
A40: 最大 | C40: － | D40: － | E40: － | F40: － | G40: =IFERROR(MAX(G6:G39),"") | H40: =IFERROR(MAX(H6:H39),"") | I40: =IFERROR(MAX(I6:I39),"") | J40: － | K40: =IFERROR(MAX(K6:K39),"") | L40: － | M40: =IFERROR(MAX(M6:M39),"") | N40: =IFERROR(MAX(N6:N39),"")
A41: 平均 | C41: － | D41: － | E41: － | F41: － | G41: =IFERROR(AVERAGE(G6:G39),"") | H41: =IFERROR(AVERAGE(H6:H39),"") | I41: =IFERROR(AVERAGE(I6:I39),"") | J41: － | K41: =IFERROR(AVERAGE(K6:K39),"") | L41: － | M41: =IFERROR(AVERAGE(M6:M39),"") | N41: =IFERROR(AVERAGE(N6:N39),"")
A42: 最小 | C42: － | D42: － | E42: － | F42: － | G42: =IFERROR(MIN(G6:G39),"") | H42: =IFERROR(MIN(H6:H39),"") | I42: =IFERROR(MIN(I6:I39),"") | J42: － | K42: =IFERROR(MIN(K6:K39),"") | L42: － | M42: =IFERROR(MIN(M6:M39),"") | N42: =IFERROR(MIN(N6:N39),"")
A43: 合計 | C43: － | D43: － | E43: － | F43: － | G43: =IFERROR(SUM(G6:G39),"") | H43: =IFERROR(SUM(H6:H39),"") | I43: =IFERROR(SUM(I6:I39),"") | J43: － | K43: =IFERROR(SUM(K6:K39),"") | L43: － | M43: =IFERROR(SUM(M6:M39),"") | N43: =IFERROR(SUM(N6:N39),"")
A44: 吉和水質管理センター運転管理月報 | J44: 平成18年８月分
A45: 日付 | B45: 曜日 | C45: 全日電力量読み値 | D45: 力測電力量読み値 | E45: 無効電力量読み値 | F45: 上水使用量読み値 | G45: 固形塩素 | H45: 脱水ケーキ | J45: No.1 | L45: No.2
G46: 使用量 | H46: 発生量 | I46: 搬出量 | J46: 返送汚泥 | L46: 返送汚泥
J47: 流 量 | L47: 流 量
C48: kwh | D48: kwh | E48: kvarh | F48: ㎥ | G48: kg | H48: ｔ | I48: ｔ | J48: ㎥ | L48: ㎥
A49: 1 | B49: 火 | C49: 694 | D49: 438.82 | E49: 2 | F49: 1016 | J49: 590074 | K49: =J49-#REF! | L49: 217242 | M49: =L49-#REF!
A50: 2 | B50: 水 | C50: 694 | D50: 438.82 | E50: 2 | F50: 1017 | H50: 1.87 | J50: 590310 | K50: =J50-J49 | L50: 217444 | M50: =L50-L49
A51: 3 | B51: 木 | C51: 694 | D51: 438.82 | E51: 2 | F51: 1017 | I51: 1.87 | J51: 590556 | K51: =J51-J50 | L51: 217673 | M51: =L51-L50
A52: 4 | B52: 金 | C52: 694 | D52: 442.75 | E52: 2.02 | F52: 1017 | J52: 590720 | K52: =J52-J51 | L52: 217820 | M52: =L52-L51
A53: 5 | B53: 土
A54: 6 | B54: 日
A55: 7 | B55: 月 | C55: 694 | D55: 445.51 | E55: 2.02 | F55: 1017 | G55: 35 | J55: 591393 | K55: =(J55-J52)/3 | L55: 218387 | M55: =(L55-L52)/3
A56: 8 | B56: 火 | C56: 694 | D56: 438.82 | E56: 2 | F56: 1017 | J56: 591530 | K56: =J56-J55 | L56: 218540 | M56: =L56-L55
A57: 9 | B57: 水 | C57: 694 | D57: 438.82 | E57: 2 | F57: 1017 | H57: 2.04 | J57: 591809 | K57: =J57-J56 | L57: 218791 | M57: =L57-L56
...

Sheet 水質管理報告
A1: 筒賀水質管理センター水質管理月報（１/２） | P1: =運転管理月報!J1
A3: 日付 | B3: 曜日 | C3: 水温 | I3: 外観 | O3: 透視度
C4: （５回/週） | I4: （５回/週） | O4: （５回/週）
C5: ℃ | I5: ― | O5: cm
C6: 流入 | D6: No．１ | E6: No．２ | F6: No．１ | G6: No．２ | H6: 放流水 | I6: 流入 | J6: No．１ | K6: No．２ | L6: No．１ | M6: No．２ | N6: 放流水 | O6: 流入 | P6: No.1 終沈 | Q6: No.2 終沈 | R6: 放流
D7: ディッチ | E7: ディッチ | F7: 終沈 | G7: 終沈 | J7: ディッチ | K7: ディッチ | L7: 終沈 | M7: 終沈
A8: =運転管理月報!A6 | B8: =TEXT(A8,"aaa")
A9: =A8+1 | B9: =TEXT(A9,"aaa") | I9: 黄灰色 | J9: 茶色 | K9: 茶色 | L9: 透明 | M9: 透明 | N9: 透明
A10: =A9+1 | B10: =TEXT(A10,"aaa") | I10: 黄灰色 | J10: 茶色 | K10: 茶色 | L10: 透明 | M10: 透明 | N10: 透明
A11: =A10+1 | B11: =TEXT(A11,"aaa") | I11: 黄灰色 | J11: 茶色 | K11: 茶色 | L11: 透明 | M11: 透明 | N11: 透明
A12: =A11+1 | B12: =TEXT(A12,"aaa") | I12: 黄灰色 | J12: 茶色 | K12: 茶色 | L12: 透明 | M12: 透明 | N12: 透明
A13: =A12+1 | B13: =TEXT(A13,"aaa") | I13: 黄灰色 | J13: 茶色 | K13: 茶色 | L13: 透明 | M13: 透明 | N13: 透明
A14: =A13+1 | B14: =TEXT(A14,"aaa")
A15: =A14+1 | B15: =TEXT(A15,"aaa")
A16: =A15+1 | B16: =TEXT(A16,"aaa") | I16: 黄灰色 | J16: 茶色 | K16: 茶色 | L16: 透明 | M16: 透明 | N16: 透明
A17: =A16+1 | B17: =TEXT(A17,"aaa") | I17: 黄灰色 | J17: 茶色 | K17: 茶色 | L17: 透明 | M17: 透明 | N17: 透明
A18: =A17+1 | B18: =TEXT(A18,"aaa") | I18: 黄灰色 | J18: 茶色 | K18: 茶色 | L18: 透明 | M18: 透明 | N18: 透明
A19: =A18+1 | B19: =TEXT(A19,"aaa") | I19: 黄灰色 | J19: 茶色 | K19: 茶色 | L19: 透明 | M19: 透明 | N19: 透明
A20: =A19+1 | B20: =TEXT(A20,"aaa") | I20: 黄灰色 | J20: 茶色 | K20: 茶色 | L20: 透明 | M20: 透明 | N20: 透明
A21: =A20+1 | B21: =TEXT(A21,"aaa")
A22: =A21+1 | B22: =TEXT(A22,"aaa")
A23: =A22+1 | B23: =TEXT(A23,"aaa") | I23: 黄灰色 | J23: 茶色 | K23: 茶色 | L23: 透明 | M23: 透明 | N23: 透明
A24: =A23+1 | B24: =TEXT(A24,"aaa") | I24: 黄灰色 | J24: 茶色 | K24: 茶色 | L24: 透明 | M24: 透明 | N24: 透明
A25: =A24+1 | B25: =TEXT(A25,"aaa") | I25: 黄灰色 | J25: 茶色 | K25: 茶色 | L25: 透明 | M25: 透明 | N25: 透明
A26: =A25+1 | B26: =TEXT(A26,"aaa") | I26: 黄灰色 | J26: 茶色 | K26: 茶色 | L26: 透明 | M26: 透明 | N26: 透明
A27: =A26+1 | B27: =TEXT(A27,"aaa") | I27: 黄灰色 | J27: 茶色 | K27: 茶色 | L27: 透明 | M27: 透明 | N27: 透明
A28: =A27+1 | B28: =TEXT(A28,"aaa")
A29: =A28+1 | B29: =TEXT(A29,"aaa")
A30: =A29+1 | B30: =TEXT(A30,"aaa") | I30: 黄灰色 | J30: 茶色 | K30: 茶色 | L30: 透明 | M30: 透明 | N30: 透明
A31: =A30+1 | B31: =TEXT(A31,"aaa") | I31: 黄灰色 | J31: 茶色 | K31: 茶色 | L31: 透明 | M31: 透明 | N31: 透明
A32: =A31+1 | B32: =TEXT(A32,"aaa") | I32: 黄灰色 | J32: 茶色 | K32: 茶色 | L32: 透明 | M32: 透明 | N32: 透明
A33: =A32+1 | B33: =TEXT(A33,"aaa") | I33: 黄灰色 | J33: 茶色 | K33: 茶色 | L33: 透明 | M33: 透明 | N33: 透明
A34: =A33+1 | B34: =TEXT(A34,"aaa") | I34: 黄灰色 | J34: 茶色 | K34: 茶色 | L34: 透明 | M34: 透明 | N34: 透明
A35: =A34+1 | B35: =TEXT(A35,"aaa")
A36: =A35+1 | B36: =TEXT(A36,"aaa")
A37: =A36+1 | B37: =TEXT(A37,"aaa") | I37: 黄灰色 | J37: 茶色 | K37: 茶色 | L37: 透明 | M37: 透明 | N37: 透明
A38: =A37+1 | B38: =TEXT(A38,"aaa") | I38: 黄灰色 | J38: 茶色 | K38: 茶色 | L38: 透明 | M38: 透明 | N38: 透明
A39: 最大 | C39: =IFERROR(MAX(C8:C38),"") | D39: =IFERROR(MAX(D8:D38),"") | E39: =IFERROR(MAX(E8:E38),"") | F39: =IFERROR(MAX(F8:F38),"") | G39: =IFERROR(MAX(G8:G38),"") | H39: =IFERROR(MAX(H8:H38),"") | I39: ― | J39: ― | K39: ― | L39: ― | M39: ― | N39: ― | O39: =IFERROR(MAX(O8:O38),"") | P39: =IFERROR(MAX(P8:P38),"") | Q39: =IFERROR(MAX(Q8:Q38),"") | R39: =IFERROR(MAX(R8:R38),"")
A40: 平均 | C40: =IFERROR(AVERAGE(C8:C38),"") | D40: =IFERROR(AVERAGE(D8:D38),"") | E40: =IFERROR(AVERAGE(E8:E38),"") | F40: =IFERROR(AVERAGE(F8:F38),"") | G40: =IFERROR(AVERAGE(G8:G38),"") | H40: =IFERROR(AVERAGE(H8:H38),"") | I40: ― | J40: ― | K40: ― | L40: ― | M40: ― | N40: ― | O40: =IFERROR(AVERAGE(O8:O38),"") | P40: =IFERROR(AVERAGE(P8:P38),"") | Q40: =IFERROR(AVERAGE(Q8:Q38),"") | R40: =IFERROR(AVERAGE(R8:R38),"")
A41: 最小 | C41: =IFERROR(MIN(C8:C38),"") | D41: =IFERROR(MIN(D8:D38),"") | E41: =IFERROR(MIN(E8:E38),"") | F41: =IFERROR(MIN(F8:F38),"") | G41: =IFERROR(MIN(G8:G38),"") | H41: =IFERROR(MIN(H8:H38),"") | I41: ― | J41: ― | K41: ― | L41: ― | M41: ― | N41: ― | O41: =IFERROR(MIN(O8:O38),"") | P41: =IFERROR(MIN(P8:P38),"") | Q41: =IFERROR(MIN(Q8:Q38),"") | R41: =IFERROR(MIN(R8:R38),"")
...

Sheet 日常機械設備
A1: 機械設備日常点検表（１/３） | H1: =運転管理月報!J1
A2: 機 器 名 | B2: No | C2: 点 検 者 | E2: 山根 悠貴 | F2: 山根 悠貴 | G2: 山根 悠貴 | H2: 山根 悠貴 | I2: 山根 悠貴
C3: 点検内容 | E3: =日常水質!I3 | F3: =日常水質!J3 | G3: =日常水質!K3 | H3: =日常水質!L3 | I3: =日常水質!M3
A4: ポンプ井 | B4: ― | C4: 内部状況確認
A5: 汚水ポンプ | B5: 1 | C5: 電流値 | D5: Ａ
C6: 吐出圧力 | D6: Mpa
C7: 異音、振動
B8: 2 | C8: 電流値 | D8: Ａ
C9: 吐出圧力 | D9: Mpa
C10: =C7
B11: ― | C11: モード確認
C12: 機種選択
A13: 自動除塵機 | C13: 油圧圧力 | D13: Mpa
C14: 異音、振動
C15: し渣量の確認
C16: 運転動作
A17: エアレーション装置 | B17: №1 | C17: 電流値 | D17: Ａ
C18: =C14
C19: モード確認
B20: №2 | C20: 電流値 | D20: Ａ
C21: =C18
C22: モード確認
B23: №3 | C23: 電流値 | D23: Ａ
C24: =C21
C25: モード確認
B26: №4 | C26: 電流値 | D26: Ａ
C27: =C24
C28: モード確認
A29: 消泡装置 | B29: ― | C29: 消泡ノズル
C30: 消泡状態
A31: 流出可動堰 | B31: 1 | C31: 開度 | D31: ㎜
B32: 2 | C32: 開度 | D32: ㎜
A33: 流出ゲート | B33: 1 | C33: 開度 | D33: ㎜
B34: 2 | C34: 開度 | D34: ㎜
A35: 連絡ゲート | B35: － | C35: 開度 | D35: ㎜
A36: 終沈汚泥掻寄機 | B36: 1 | C36: 電流値 | D36: Ａ
C37: 異音、振動等
B38: 2 | C38: 電流値 | D38: Ａ
C39: =C37
A40: スカムスキマー | B40: 1 | C40: 動作状況
...

Sheet 日常電気設備
A1: 電気設備日常点検（１/３） | K1: =運転管理月報!J1
G2: =日常水質!I3 | H2: =日常水質!J3 | I2: =日常水質!K3 | J2: =日常水質!L3 | K2: =日常水質!M3
A3: 電 気 室 | B3: 引込・受電 | C3: 電圧 | F3: KV
F4: モード
C5: 力率 | F5: ψ
C6: 電流 | F6: A
F7: モード
C8: 普通電力量（×１０ｋw） | F8: 読み
F9: 使用量
C10: 引込・受電設定 | F10: 手動/自動
F11: 切/入
B12: 変圧器 | C12: 主変圧器温度 | F12: ℃
C13: 異音、脱臭の有無 | F13: 有・無
B14: 低 圧 分 岐 | C14: 動力（２１０V） 電圧 | F14: V
F15: モード
C16: 動力（２１０V） 電流 | F16: A
F17: モード
C18: 照明(210-105V) 電流 | F18: A
F19: モード
C20: 低圧分岐設備 | F20: 買電/自家発
C21: 沈砂池ポンプ設備 | F21: 読み
C22: （×１ｋｗｈ） | F22: 使用量
C23: 水処理設備（１） | F23: 読み
C24: （×１ｋｗｈ） | F24: 使用量
C25: 水処理設備（２） | F25: 読み
C26: （×１ｋｗｈ） | F26: 使用量
C27: 汚泥処理設備電力量 | F27: 読み
C28: （×１ｋｗｈ） | F28: 使用量
C29: No.１ コンデンサー(電磁接触器) | F29: 切/入
C30: No.２ コンデンサー(電磁接触器) | F30: 切/入
C31: No.３ コンデンサー(電磁接触器) | F31: 切/入
A32: 備 考
A37: 電気設備日常点検（２/３） | K37: =K1
B38: 機器名 | D38: 点 検 者 氏 名
D39: 点 検 内 容
A40: 計 装 設 備 | B40: Nｏ．１オキシデーションディッチＤＯ計 | D40: 外観の確認
D41: 指示状況の確認
D42: ＤＯ値 | F42: ㎎/ℓ
B43: Nｏ．２オキシデーションディッチＤＯ計 | D43: 外観の確認
D44: 指示状況の確認
...

Sheet 主要機器運転時間
A1: 筒 賀 水 質 管 理 セ ン ター
A3: 主 要 機 器 運 転 時 間
A5: 46083 | D5: ～ | F5: =A5+4
A7: 機 器 名 称 | D7: 月 | E7: 火 | F7: 水 | G7: 木 | H7: 金
A8: NO.1主ポンプ | C8: hr
A9: NO.2主ポンプ | C9: hr
A10: NO.1エアレーション装置 | C10: hr
A11: NO.2エアレーション装置 | C11: hr
A12: NO.3エアレーション装置 | C12: hr
A13: NO.4エアレーション装置 | C13: hr
A14: №1終沈汚泥かき寄せ機 | C14: hr
A15: №2終沈汚泥かき寄せ機 | C15: hr
A16: NO.1返送汚泥ポンプ | C16: hr
A17: NO.2返送汚泥ポンプ | C17: hr
A18: NO.3返送汚泥ポンプ | C18: hr
A19: NO.4返送汚泥ポンプ | C19: hr
... A29: 発電機 | C29: hr
A30: 備考
A39: 筒 賀 水 質 管 理 セ ン ター
A41: 主 要 機 器 運 転 時 間
A43: 46090 | D43: ～ | F43: =A43+4
A45: 機 器 名 称 | D45: 月 | E45: 火 | F45: 水 | G45: 木 | H45: 金
A46: NO.1主ポンプ | C46: hr
A47: NO.2主ポンプ | C47: hr
A48: NO.1エアレーション装置 | C48: hr
A49: NO.2エアレーション装置 | C49: hr
A50: NO.3エアレーション装置 | C50: hr
A51: NO.4エアレーション装置 | C51: hr
A52: №1終沈汚泥かき寄せ機 | C52: hr
A53: №2終沈汚泥かき寄せ機 | C53: hr
A54: NO.1返送汚泥ポンプ | C54: hr
A55: NO.2返送汚泥ポンプ | C55: hr
A56: NO.3返送汚泥ポンプ | C56: hr
A57: NO.4返送汚泥ポンプ | C57: hr
... A67: 発電機 | C67: hr
A68: 備考
A77: 筒 賀 水 質 管 理 セ ン ター
A79: 主 要 機 器 運 転 時 間
A81: 46097 | D81: ～ | F81: =A81+3
A83: 機 器 名 称 | D83: 月 | E83: 火 | F83: 水 | G83: 木 | H83: 金
...
